utest failure: <lambda>
  arg 0=0
  arg 1=1
  arg x='x'
  arg y='y'
  expected value: True
  returned value: False

utest failure: raise_unexpected
  expected value: True
  raised exception: Exception('unexpected',)

utest failure: <lambda>
  expected exception: Exception('expected',)
  returned value: True

utest failure: raise_unexpected
  expected exception: Exception('expected',)
  raised exception: Exception('unexpected',)

utest failure: range
  arg 0=0
  expected sequence: [0]
  returned sequence: []

utest failure: <lambda>
  expected sequence: [0]
  returned value: 0
  raised exception: TypeError("'int' object is not iterable",)

utest failure: 'utest_val fail test'
  expected value: True
  returned value: False

